Workbook

Sheet Datos voluntarios
A1: N° | B1: Filial | C1: Calidad de voluntario | D1: Nombres voluntario | E1: Apellidos voluntarios | F1: RUT | G1: Fecha de ingreso | H1: Fecha nacimiento | I1: Correo | J1: Direccion | K1: Telefono | L1: Cargo | M1: Edad | N1: Edad de ingreso a CRC | O1: Antigüedad | P1: Género | Q1: Instructores de PPAA Básico | R1: Instructores de PPAA Avanzado | S1: Instructores doctrina | T1: TOT | U1: SPAC | V1: ENI | W1: CPI | X1: IM-PMER | Y1: EIEM | Z1: RIT finanzas | AA1: Podología | AB1: Matrona | AC1: TENS | AD1: Operador de salud en emergencia | AE1: Monitor ed. sexual | AF1: RCF | AG1: RIT agua | AH1: Titulo socorrista | AI1: Instructor en metodología participativa | AJ1: Supervisor en prevención de desastres | AK1: Instructor en prevención de desastres | AL1: Enfermeria
B2: Almendral | C2: Activo | D2: Lidia Ester | E2: Fontalba Guerrero | F2: 7.470.371-2 | G2: 34780 | H2: 21495 | I2: lidia.fontalbaguerrero@gmail.com | J2: Retamo # 758 | K2: 991413562 | L2: Presidente | M2: =(TODAY()-H2)/365 -> 67.142466 | N2: =(G2-H2)/365 -> 36.39726 | O2: =(TODAY()-G2)/365 -> 30.745205 | P2: F | Q2: 0 | R2: 0 | S2: 0
B3: Almendral | C3: Activo | D3: Gilda del C | E3: Gómez Aburto | F3: 7.168.729-5 | G3: 34836 | H3: 20538 | I3: gildagomez1956@gmail.com | J3: Atalaya 109 Playa Ancha | K3: 946321495 | L3: Secretario/a | M3: =(TODAY()-H3)/365 -> 69.764384 | N3: =(G3-H3)/365 -> 39.172603 | O3: =(TODAY()-G3)/365 -> 30.591781 | P3: F | Q3: 0 | R3: 0 | S3: 0
B4: Almendral | C4: Activo | D4: Karina Emilia | E4: González Espinoza | F4: 12974043-4 | G4: 43390 | H4: 27973 | I4: yzakari@hotmail.com | J4: Río Riñihue 864Viña del Mar | K4: 979980559 | L4: Director/a de Finanzas | M4: =(TODAY()-H4)/365 -> 49.394521 | N4: =(G4-H4)/365 -> 42.238356 | O4: =(TODAY()-G4)/365 -> 7.1561644 | P4: F | Q4: 0 | R4: 0 | S4: 0
B5: Almendral | C5: Activo | D5: Magda Lourdes | E5: Valle Quezada | F5: 12.845.875-1 | G5: 43390 | H5: 27532 | I5: S/I | J5: Arcilla 698 C Barón | K5: 953019125 | L5: Voluntario/a | M5: =(TODAY()-H5)/365 -> 50.60274 | N5: =(G5-H5)/365 -> 43.446575 | O5: =(TODAY()-G5)/365 -> 7.1561644 | P5: F | Q5: 0 | R5: 0 | S5: 0
B6: Almendral | C6: Activo | D6: Silvia del C | E6: Díaz Bolívar | F6: 5.016.242-7 | G6: 34801 | H6: 16800 | I6: silvitadiazbolivar@gmail.com | J6: villa Navaríno20 Miraflores | K6: 947102600 | L6: Director/a de Salud | M6: =(TODAY()-H6)/365 -> 80.005479 | N6: =(G6-H6)/365 -> 49.317808 | O6: =(TODAY()-G6)/365 -> 30.687671 | P6: F | Q6: 0 | R6: 0 | S6: 0
B7: Almendral | C7: Activo | D7: Rosa Ester | E7: Salazar Fuentealba | F7: 6.794.473-9 | G7: 44874 | H7: 19787 | I7: rosa.ester.salazar53@gmail.com | J7: San Luis 927 Placeres | K7: 996174648 | L7: Director/a de Bienestar social | M7: =(TODAY()-H7)/365 -> 71.821918 | N7: =(G7-H7)/365 -> 68.731507 | O7: =(TODAY()-G7)/365 -> 3.090411 | P7: F | Q7: 0 | R7: 0 | S7: 0
B8: Curanilahue | C8: Llamada | D8: Paz | E8: Acosta Ramírez | F8: 23.095.215-9 | G8: 45366 | H8: 40034 | I8: Pazitaacosta9@gmail.com | J8: S/I | K8: S/I | L8: Voluntario/a | M8: =(TODAY()-H8)/365 -> 16.350685 | N8: =(G8-H8)/365 -> 14.608219 | O8: =(TODAY()-G8)/365 -> 1.7424658 | P8: F | Q8: 0 | R8: 0 | S8: 0
B9: Alto Hopicio | C9: Activo | D9: Maria | E9: Gautier | F9: 14.443.487-0 | G9: 43466 | H9: 26239 | I9: S/I | J9: Alto hospicio | K9: 942787221 | M9: =(TODAY()-H9)/365 -> 54.145205 | N9: =(G9-H9)/365 -> 47.19726 | O9: =(TODAY()-G9)/365 -> 6.9479452 | P9: F
B10: Alto Hopicio | C10: Activo | D10: Carla | E10: Ortiz | F10: 19.493.798-9 | G10: 39448 | H10: 35633 | I10: S/I | J10: Alto hospicio | K10: 965016697 | M10: =(TODAY()-H10)/365 -> 28.408219 | N10: =(G10-H10)/365 -> 10.452055 | O10: =(TODAY()-G10)/365 -> 17.956164 | P10: F
B11: Alto Hopicio | C11: Activo | D11: Martha | E11: Valle | F11: 14.755.941-0 | G11: 43101 | H11: 23030 | I11: S/I | J11: Alto hospicio | K11: 987602052 | M11: =(TODAY()-H11)/365 -> 62.936986 | N11: =(G11-H11)/365 -> 54.989041 | O11: =(TODAY()-G11)/365 -> 7.9479452 | P11: F
B12: Alto Hopicio | C12: Activo | D12: Carla | E12: Arcaya | F12: 14.761.648-1 | G12: 43101 | H12: 25427 | I12: S/I | J12: Alto hospicio | K12: 991770543 | M12: =(TODAY()-H12)/365 -> 56.369863 | N12: =(G12-H12)/365 -> 48.421918 | O12: =(TODAY()-G12)/365 -> 7.9479452 | P12: F
B13: Alto Hopicio | C13: Activo | D13: Maria | E13: Canova | F13: 22.284.412-4 | G13: 42370 | H13: 28313 | I13: S/I | J13: Alto hospicio | K13: 963081766 | M13: =(TODAY()-H13)/365 -> 48.463014 | N13: =(G13-H13)/365 -> 38.512329 | O13: =(TODAY()-G13)/365 -> 9.9506849 | P13: F
B14: Alto Hopicio | C14: Activo | D14: Benjamin | E14: Neyra | F14: 22.381.707-6 | G14: 45292 | H14: 39187 | I14: S/I | J14: Alto hospicio | K14: 963081766 | M14: =(TODAY()-H14)/365 -> 18.671233 | N14: =(G14-H14)/365 -> 16.726027 | O14: =(TODAY()-G14)/365 -> 1.9452055 | P14: M
B15: Alto Hopicio | C15: Activo | D15: Daysi | E15: Saavedra | F15: 22.667.837-9 | G15: 45658 | H15: 38387 | I15: S/I | J15: Alto hospicio | K15: 923680294 | M15: =(TODAY()-H15)/365 -> 20.863014 | N15: =(G15-H15)/365 -> 19.920548 | O15: =(TODAY()-G15)/365 -> 0.94246575 | P15: F
B16: Alto Hopicio | C16: Activo | D16: Rodrigo | E16: Astorga | F16: 12.438.429-k | G16: 45292 | H16: 26841 | I16: S/I | J16: Alto hospicio | K16: 956618713 | M16: =(TODAY()-H16)/365 -> 52.49589 | N16: =(G16-H16)/365 -> 50.550685 | O16: =(TODAY()-G16)/365 -> 1.9452055 | P16: M
B17: Alto Hopicio | C17: Activo | D17: Hugo | E17: Andrade | F17: 25.481.290-0 | G17: 43101 | H17: 34728 | I17: S/I | J17: Alto hospicio | K17: 993102961 | M17: =(TODAY()-H17)/365 -> 30.887671 | N17: =(G17-H17)/365 -> 22.939726 | O17: =(TODAY()-G17)/365 -> 7.9479452 | P17: M
B18: Chillán | C18: Llamada | D18: Bárbara Mayary | E18: Acuña García | F18: 15098093-0 | G18: 39509 | H18: 30264 | I18: angelmayary@hotmail.com | J18: S/I | K18: S/I | L18: Voluntario/a | M18: =(TODAY()-H18)/365 -> 43.117808 | N18: =(G18-H18)/365 -> 25.328767 | O18: =(TODAY()-G18)/365 -> 17.789041 | P18: F | Q18: 0 | R18: 0 | S18: 0
B19: Concepción | C19: Llamada | D19: Paulina Noemi | E19: Acuña Mellado | F19: 20.154.308-8 | G19: 42892 | H19: 36233 | I19: paulinanoemi13@gma il.com | J19: Psje 5 Casa 3596, San Pedro de la Paz | K19: 9410048 75 | L19: Voluntario/a | M19: =(TODAY()-H19)/365 -> 26.764384 | N19: =(G19-H19)/365 -> 18.243836 | O19: =(TODAY()-G19)/365 -> 8.5205479 | P19: F | Q19: 0 | R19: 0 | S19: 1
B20: Lebu | C20: Llamada | D20: Danitza | E20: Aguayo Ramirez | F20: 19.364.296-9 | G20: 44592 | H20: 35461 | I20: S/I | J20: S/I | K20: S/I | L20: Voluntario/a | M20: =(TODAY()-H20)/365 -> 28.879452 | N20: =(G20-H20)/365 -> 25.016438 | O20: =(TODAY()-G20)/365 -> 3.8630137 | P20: F | Q20: 0 | R20: 0 | S20: 0
B21: Lota | C21: Llamada | D21: Juana | E21: Aguayo Salinas | F21: 12.926.126-9 | G21: 45597 | H21: 27701 | I21: S/I | J21: S/I | K21: S/I | L21: Voluntario/a | M21: =(TODAY()-H21)/365 -> 50.139726 | N21: =(G21-H21)/365 -> 49.030137 | O21: =(TODAY()-G21)/365 -> 1.109589 | P21: F | Q21: 0 | R21: 0 | S21: 0
B22: Iquique | C22: Llamada | D22: María Yaquelin | E22: Aguilar Urias | F22: 26.448.785-4 | G22: 45636 | H22: 33838 | I22: Aguilarurias.m@gmail.com | J22: S/I | K22: S/I | L22: Voluntario/a | M22: =(TODAY()-H22)/365 -> 33.326027 | N22: =(G22-H22)/365 -> 32.323288 | O22: =(TODAY()-G22)/365 -> 1.0027397 | P22: F
B23: Tocopilla | C23: Llamada | D23: Emily alejandra | E23: Aguilera pizarro | F23: 21.562.229-0 | G23: 45356 | H23: 38104 | I23: Emilyyy2004.ea39@gmail.com | J23: S/I | K23: S/I | M23: =(TODAY()-H23)/365 -> 21.638356 | N23: =(G23-H23)/365 -> 19.868493 | O23: =(TODAY()-G23)/365 -> 1.769863 | P23: F
B24: Ancud | C24: Activo | D24: MARÍA ANGÉLICA | E24: AGUAYO OJEDA | F24: 8.252.803-2 | G24: 45056 | H24: 20382 | I24: Angelica.aguayo.o@gmail.com | J24: Ancud | K24: 989730502 | M24: =(TODAY()-H24)/365 -> 70.191781 | N24: =(G24-H24)/365 -> 67.6 | O24: =(TODAY()-G24)/365 -> 2.5917808 | P24: F
B25: Ancud | C25: Activo | D25: ZILIA DEL CÁRMEN | E25: AMPUERO BARRIENTOS | F25: 7.459.810 -2 | G25: 31523 | H25: 20002 | I25: Ziliampuero1954@gmail.com | J25: Anibal Pinto N° 889 Ancud | K25: 965807436 | M25: =(TODAY()-H25)/365 -> 71.232877 | N25: =(G25-H25)/365 -> 31.564384 | O25: =(TODAY()-G25)/365 -> 39.668493 | P25: F
B26: Ancud | C26: Activo | D26: MARIA EDITH | E26: BARRIA BARRIA | F26: 7.134.883 -0 | G26: 41248 | H26: 18500 | I26: barrimaria@gmail.com | J26: Lautaro N°899 Ancud | K26: 945555863 | M26: =(TODAY()-H26)/365 -> 75.347945 | N26: =(G26-H26)/365 -> 62.323288 | O26: =(TODAY()-G26)/365 -> 13.024658 | P26: F
B27: Ancud | C27: Activo | D27: SONIA DEL CÁRMEN | E27: CARO BARRIA | F27: 7.356.910 -9 | G27: 37672 | H27: 19382 | I27: carobarriasonia@gmail.com | J27: Los Alerces N°515 Ancud | K27: 933314048 | M27: =(TODAY()-H27)/365 -> 72.931507 | N27: =(G27-H27)/365 -> 50.109589 | O27: =(TODAY()-G27)/365 -> 22.821918 | P27: F
B28: Ancud | C28: Activo | D28: MARGARITA GUADALUPE | E28: MATURANA MOLINA | F28: 7.797.067 -3 | G28: 37672 | H28: 20244 | I28: maigammm@gmail.com | J28: Prat. Pje. Oriente N°35 Ancud | K28: 997069613 | M28: =(TODAY()-H28)/365 -> 70.569863 | N28: =(G28-H28)/365 -> 47.747945 | O28: =(TODAY()-G28)/365 -> 22.821918 | P28: F
B29: Ancud | C29: Activo | D29: JENNIE DEL CÁRMEN | E29: MUÑOZ ALVARADO | F29: 8.631.300 -6 | G29: 41233 | H29: 20538 | I29: mamijennie@hotmail.com | J29: La Coruña N° 364 Ancud | K29: 988076304 | M29: =(TODAY()-H29)/365 -> 69.764384 | N29: =(G29-H29)/365 -> 56.69863 | O29: =(TODAY()-G29)/365 -> 13.065753 | P29: F
B30: Ancud | C30: Activo | D30: RUTH VERÓNICA | E30: OYARZO GALLARDO | F30: 7.851.711 -5 | G30: 44767 | H30: 21750 | I30: rveronica.oyarzog@gmail.com | J30: Los Carrera N°990 Ancud | K30: 966375661 | M30: =(TODAY()-H30)/365 -> 66.443836 | N30: =(G30-H30)/365 -> 63.060274 | O30: =(TODAY()-G30)/365 -> 3.3835616 | P30: F
B31: Ancud | C31: Activo | D31: MARIA ALONDRA | E31: REUTER MIRANDA | F31: 6.681.789 -k | G31: 31030 | H31: 18130 | I31: aluette@live.com | J31: Errazuriz N° 350 Ancud | K31: 966048985 | M31: =(TODAY()-H31)/365 -> 76.361644 | N31: =(G31-H31)/365 -> 35.342466 | O31: =(TODAY()-G31)/365 -> 41.019178 | P31: F
B32: Ancud | C32: Activo | D32: REBECA AYDE | E32: SANTANA DÍAZ | F32: 8.258.583 -4 | G32: 45056 | H32: 20110 | I32: rebecasantana55@gmail.com | J32: Ancud | K32: 988003435 | M32: =(TODAY()-H32)/365 -> 70.936986 | N32: =(G32-H32)/365 -> 68.345205 | O32: =(TODAY()-G32)/365 -> 2.5917808 | P32: F
B33: SR Atacama Coquimbo | C33: Llamada | D33: Josefa | E33: Aguirre Varas | F33: 22.957.475-2 | G33: 45061 | H33: 39871 | I33: Jo.bts.2009@gmail.com | J33: S/I | K33: S/I | L33: Voluntario/a | M33: =(TODAY()-H33)/365 -> 16.79726 | N33: =(G33-H33)/365 -> 14.219178 | O33: =(TODAY()-G33)/365 -> 2.5780822 | P33: F | Q33: 0 | R33: 0 | S33: 0
B34: Nancagua | C34: Llamada | D34: Gabriel | E34: Ahumada Diaz | F34: 14.302.685-k | G34: 44848 | H34: S/I | I34: S/I | J34: S/I | K34: S/I | M34: =(TODAY()-H34)/365 -> #VALUE! | N34: =(G34-H34)/365 -> #VALUE! | O34: =(TODAY()-G34)/365 -> 3.1616438 | P34: M
B35: Angol | C35: Activo | D35: Sonia del Carmen | E35: Saldias Meza | F35: 7.265.289-4 | G35: 28978 | H35: 21074 | I35: snsaldias@gmail.com | J35: Pampa Graneros 1506 | K35: 942927464 | L35: Voluntario/a | M35: =(TODAY()-H35)/365 -> 68.29589 | N35: =(G35-H35)/365 -> 21.654795 | O35: =(TODAY()-G35)/365 -> 46.641096 | P35: F | Q35: 0 | R35: 0 | S35: 0
B36: Angol | C36: Activo | D36: Ruby Nelly | E36: Aguirre Pineda | F36: 9.789.296-7 | G36: 32588 | H36: 24034 | I36: rubynellyaguirrep@gmail.com | J36: Amancay 1242 | K36: 949186075 | L36: Voluntario/a | M36: =(TODAY()-H36)/365 -> 60.186301 | N36: =(G36-H36)/365 -> 23.435616 | O36: =(TODAY()-G36)/365 -> 36.750685 | P36: F | Q36: 0 | R36: 0 | S36: 0
B37: Parral | C37: Llamada | D37: Sara María José | E37: Ahumada Placencio | F37: S/I | G37: S/I | H37: S/I | I37: S/I | J37: S/I | K37: S/I | L37: Director/a de Salud | O37: =(TODAY()-G37)/365 -> #VALUE! | P37: F | Q37: 0 | R37: 0 | S37: 0
B38: Loncoche | C38: Llamada | D38: Paula | E38: Aichele C. | F38: 21.645.926-1 | G38: 44867 | H38: S/I | I38: S/I | J38: S/I | K38: 9985720 42 | L38: Director/a de Comunicaciones | M38: 0 | O38: =(TODAY()-G38)/365 -> 3.109589 | P38: F | Q38: 0 | R38: 0 | S38: 0
B39: Talagante | C39: Llamada | D39: Antonia Millaray | E39: Alarcon Nuñez | F39: 20.985.936-K | G39: 43112 | H39: 37330 | I39: antonia.alarcon2020@umce.cl | J39: Arturo Prat 1039 Talagante | K39: 991424570 | M39: =(TODAY()-H39)/365 -> 23.758904 | N39: =(G39-H39)/365 -> 15.841096 | O39: =(TODAY()-G39)/365 -> 7.9178082 | P39: F
B40: Angol | C40: Activo | D40: Rosalbina del Carmen | E40: Campos Paredes | F40: 6.841.520-9 | G40: 30302 | H40: 20321 | I40: S/I | J40: General Lagos 286 | K40: 995133160 | L40: Voluntario/a | M40: =(TODAY()-H40)/365 -> 70.358904 | N40: =(G40-H40)/365 -> 27.345205 | O40: =(TODAY()-G40)/365 -> 43.013699 | P40: F | Q40: 0 | R40: 0 | S40: 0
...

Sheet Datos filial
A1: N° | B1: Filial | C1: Sede regional | D1: Voluntarios activos | E1: Voluntarios de llamada | F1: RUT | G1: Dirección | H1: Teléfono contacto | I1: Fecha ultima elecciones | J1: Instagram | K1: Tiene al menos una red social? | L1: Persona dedicada a redes | M1: Cambiar uniforme ceremonial | N1: Cambiar Color azul Chaquetas gestión del riesgo | O1: Voluntarios sin capacitación | P1: Voluntarios sin PPAA | Q1: Voluntarios sin Doctrina | R1: Voluntarios con título específico | S1: Instructores de PPAA | T1: Instructores doctrina | U1: Club adulto mayor | V1: Res. San. Policlinico | W1: Acción migratoria | X1: Acción situación de calle | Y1: Filial con Antena y Radio Teleco | Z1: Voluntarios con hoja de vida actualizada | AA1: Voluntariado con credencial actualizada | AB1: Filial realiza charlas estatutos y reglamentos? | AC1: Acción cambio climático | AD1: Acciones PGI (protección, género, inclusión) | AE1: Acción CEA (Rendición cuentas a la comunidad) | AF1: Kits alimentos entregados | AG1: Kits higiene entregados | AH1: Kits abrigo entregados | AI1: Voluntarios capacitados en AA | AJ1: Voluntarios capacitados en SPAC | AK1: Voluntarios capacitados en SMAPS | AL1: Voluntarios capacitados en RCF | AM1: Voluntarios capacitados en Manejo Redes | AN1: Voluntarios capacitados en Balances y EERR | AO1: N° personas capacitados en primeros auxilios (comunidad) | AP1: Cantidad Personal rentado | AQ1: Cantidad Unidades Educativas Colegios | AR1: Prioridad Sustentabilidad financiera | AS1: Prioridad Manejo tecnologías | AT1: Prioridad políticas del voluntariado | AU1: Prioridad Liderazgo y estatutos | AV1: Prioridad Derecho internacional y cambio climático | AW1: Preferencia capacitacion | AX1: Relevancia 2024 Gestión del riesgo | AY1: Relevancia 2024 Salud | AZ1: Relevancia 2024 Bienestar Social | BA1: Relevancia 2024 Juventud | BB1: Financiamiento | BC1: Comentario otro financiamiento | BD1: Encuesta confiable? (prioridades y relevancia
B2: Almendral | C2: Valparaíso | D2: 7 | E2: 0 | F2: 70512176-1 | G2: Independencia 2978 | H2: 991413562 | I2: S/I | K2: Sí | L2: No | M2: No | N2: No | O2: No | P2: 0 | Q2: 0 | R2: 0 | S2: 0 | T2: 0 | U2: Sí | V2: No | W2: No | X2: Sí | Y2: No | Z2: Sí | AA2: Sí | AB2: No | AC2: No | AD2: No | AE2: No | AF2: 0 | AG2: 0 | AH2: 160 | AI2: 0 | AJ2: 0 | AK2: 0 | AL2: 0 | AM2: 0 | AN2: 0 | AO2: 0 | AP2: 0 | AQ2: 0 | AR2: 5 | AS2: 4 | AT2: S/I | AU2: S/I | AV2: S/I | AW2: Presencial | AX2: S/I | AY2: 1 | AZ2: 2 | BA2: S/I | BB2: Arriendo | BD2: 0
B3: Angol | C3: Araucanía | D3: 20 | E3: 22 | F3: 70672737-K | G3: Lautaro N° 143 | H3: 96519624 | I3: 44531 | J3: Cr.filialangol | K3: Sí | L3: Sí | M3: No | N3: No | O3: No | P3: 0 | Q3: 0 | R3: 0 | S3: 0 | T3: 1 | U3: No | V3: Sí | W3: No | X3: Sí | Y3: Sí | Z3: Sí | AA3: No | AB3: No | AC3: No | AD3: Sí | AE3: Sí | AF3: 29 | AG3: 29 | AH3: 17 | AI3: 1 | AJ3: 0 | AK3: 0 | AL3: 0 | AM3: 0 | AN3: 0 | AO3: 0 | AP3: 2 | AQ3: 0 | AR3: 4 | AS3: 5 | AT3: 2 | AU3: 1 | AV3: 3 | AW3: Online | AX3: 1 | AY3: 3 | AZ3: 2 | BA3: 4 | BB3: Arriendo | BD3: 1
B4: Antofagasta | C4: Antofagasta | D4: 25 | E4: 5 | F4: 70672705-1 | G4: Calle Adamson 3354 | H4: 722779272 | I4: 44866 | J4: Cruzrojachilena_antofagasta | K4: Sí | L4: Sí | M4: Sí | N4: Sí | O4: Sí | P4: 0 | Q4: 9 | R4: 1 | S4: 1 | T4: 0 | U4: Sí | V4: Sí | W4: Sí | X4: Sí | Y4: Sí | Z4: Sí | AA4: Sí | AB4: No | AC4: No | AD4: Sí | AE4: No | AF4: 70 | AG4: 70 | AH4: 40 | AI4: 0 | AJ4: 0 | AK4: 0 | AL4: 10 | AM4: 1 | AN4: 0 | AO4: 0 | AP4: 0 | AQ4: 0 | AR4: 5 | AS4: 2 | AT4: 1 | AU4: 3 | AV4: 4 | AW4: Presencial | AX4: 3 | AY4: 1 | AZ4: 4 | BA4: 2 | BB4: Cursos PAA | BD4: 1
B5: Arica y Parinacota | C5: Arica Parinacota Tarapacá | D5: 23 | E5: 20 | F5: 70.672.700-0 | G5: San Marcos 356 | H5: 975855192 | I5: 45200 | J5: cruzroja_arica | K5: Sí | L5: Sí | M5: No | N5: Sí | O5: Sí | P5: S/I | Q5: S/I | R5: 1 | S5: 3 | T5: 1 | U5: No | V5: Sí | W5: Sí | X5: Sí | Y5: No | Z5: Sí | AA5: Sí | AB5: Sí | AC5: No | AD5: No | AE5: Sí | AF5: 0 | AG5: 100 | AH5: 20 | AI5: 6 | AJ5: 0 | AK5: 0 | AL5: 6 | AM5: 0 | AN5: 1 | AO5: 0 | AP5: 1 | AQ5: 5 | AR5: 3 | AS5: 2 | AT5: 4 | AU5: 5 | AV5: 1 | AW5: Online | AX5: 1 | AY5: 2 | AZ5: 3 | BA5: 4 | BB5: Subvencíón municipal | BD5: 1
B6: Bulnes | C6: Biobío y Ñuble | D6: 9 | E6: 1 | F6: 70512196-6 | G6: Victor Bianchi N°99 - Comuna Bulnes | H6: 796611917 | I6: 2017 | K6: No | L6: No | M6: Sí | N6: No | O6: Sí | P6: 7 | Q6: 7 | R6: 0 | S6: 0 | T6: 1 | U6: No | V6: No | W6: No | X6: No | Y6: No | Z6: Sí | AA6: Sí | AB6: Sí | AC6: Sí | AD6: Sí | AE6: Sí | AF6: 0 | AG6: 0 | AH6: 0 | AI6: 0 | AJ6: 0 | AK6: 0 | AL6: 0 | AM6: 0 | AN6: 0 | AO6: 0 | AP6: 0 | AQ6: 0 | AR6: 2 | AS6: 4 | AT6: 1 | AU6: 3 | AV6: 5 | AW6: Online | AX6: 2 | AY6: 3 | AZ6: 1 | BA6: 4 | BB6: Subvencíón municipal | BC6: Y aportes voluntarios hogar de ancianos | BD6: 1
B7: Cabrero | C7: Biobío y Ñuble | D7: 12 | E7: 3 | F7: 70672795-7 | G7: Calle Palacios s/n, orilla de carretera, Cabrero. | H7: 999698836 | I7: 45047 | J7: Cruzrojacabrero | K7: Sí | L7: Sí | M7: No | N7: Sí | O7: Sí | P7: 4 | Q7: 2 | R7: 0 | S7: 0 | T7: 2 | U7: Sí | V7: Sí | W7: No | X7: Sí | Y7: No | Z7: No | AA7: No | AB7: No | AC7: No | AD7: Sí | AE7: No | AF7: 56 | AG7: 28 | AH7: 0 | AI7: 1 | AJ7: 0 | AK7: 0 | AL7: 0 | AM7: 0 | AN7: 0 | AO7: 0 | AP7: 0 | AQ7: 0 | AR7: 4 | AS7: 5 | AT7: 2 | AU7: 1 | AV7: 3 | AW7: Online | AX7: 2 | AY7: 1 | AZ7: 3 | BA7: 4 | BB7: Subvencíón municipal | BD7: 1
B8: Caldera | C8: Atacama-Coquimbo | D8: 25 | E8: 5 | F8: 70672708-6 | G8: Gallo 70 | H8: 9320202907 | I8: 44652 | K8: No | L8: No | M8: No | N8: No | O8: Sí | P8: 5 | Q8: 5 | R8: 1 | S8: 1 | T8: 0 | U8: Sí | V8: Sí | W8: No | X8: Sí | Y8: Sí | Z8: Sí | AA8: No | AB8: Sí | AC8: No | AD8: No | AE8: No | AF8: 0 | AG8: 0 | AH8: 0 | AI8: 0 | AJ8: 0 | AK8: 0 | AL8: 0 | AM8: 0 | AN8: 0 | AO8: 0 | AP8: 0 | AQ8: 0 | AR8: S/I | AS8: S/I | AT8: S/I | AU8: S/I | AV8: S/I | AW8: Presencial | AX8: S/I | AY8: 1 | AZ8: 2 | BA8: S/I | BB8: Arriendo | BC8: Y policlínicos, subvención municipal | BD8: 0
B9: Cañete | C9: Biobío y Ñuble | D9: 24 | E9: 8 | F9: 70672735-5 | G9: Arturo Prat N° 437 | H9: 442918911 | I9: 45505 | J9: cruz roja fililal cañete | K9: Sí | L9: Sí | M9: Sí | N9: No | O9: Sí | P9: 3 | Q9: 5 | R9: 2 | S9: 1 | T9: 0 | U9: Sí | V9: No | W9: No | X9: Sí | Y9: No | Z9: Sí | AA9: Sí | AB9: Sí | AC9: Sí | AD9: Sí | AE9: Sí | AF9: 15 | AG9: 47 | AH9: 29 | AI9: 0 | AJ9: 0 | AK9: 0 | AL9: 0 | AM9: 0 | AN9: 0 | AO9: 0 | AP9: 1 | AQ9: 1 | AR9: 5 | AS9: 4 | AT9: 3 | AU9: 2 | AV9: 1 | AW9: Online | AX9: 1 | AY9: 3 | AZ9: 2 | BA9: 4 | BB9: Arriendo | BD9: 0
B10: Capitán Pastene | C10: Araucanía | D10: 20 | E10: 4 | F10: 65191583-K | G10: Garibaldi 708 | H10: 98376158 | I10: 2020 | K10: Sí | L10: No | M10: No | N10: Sí | O10: Sí | P10: 18 | Q10: 18 | R10: 0 | S10: 0 | T10: 0 | U10: Sí | V10: No | W10: No | X10: No | Y10: No | Z10: Sí | AA10: No | AB10: No | AC10: No | AD10: No | AE10: No | AF10: 48 | AG10: 36 | AH10: 96 | AI10: 0 | AJ10: 0 | AK10: 0 | AL10: 0 | AM10: 4 | AN10: 2 | AO10: 2 | AP10: 0 | AQ10: 0 | AR10: 5 | AS10: 4 | AT10: 3 | AU10: 2 | AV10: 1 | AW10: Presencial | AX10: 1 | AY10: 3 | AZ10: 2 | BA10: 4 | BB10: Otro | BC10: Beneficios y arriendo esporádico | BD10: 0
B11: Carahue | C11: Araucanía | D11: 21 | E11: 0 | F11: 70672747-7 | G11: Avenida Ercilla 260 | H11: 997710238 | I11: 43586 | K11: Sí | L11: No | M11: No | N11: No | O11: Sí | P11: 9 | Q11: 14 | R11: 0 | S11: 0 | T11: 0 | U11: Sí | V11: No | W11: No | X11: Sí | Y11: No | Z11: Sí | AA11: No | AB11: Sí | AC11: No | AD11: No | AE11: No | AF11: 30 | AG11: 50 | AH11: 210 | AI11: 0 | AJ11: 0 | AK11: 0 | AL11: 0 | AM11: 0 | AN11: 0 | AO11: 0 | AP11: 0 | AQ11: 0 | AR11: 5 | AS11: 2 | AT11: 4 | AU11: 1 | AV11: 3 | AW11: Mixta | AX11: 2 | AY11: 3 | AZ11: 1 | BA11: 4 | BB11: Arriendo | BD11: 1
B12: Cartagena | C12: Valparaíso | D12: 13 | E12: 0 | F12: 70512189-3 | G12: San Antonio 398 | H12: 979844862 | I12: 45474 | J12: CRUZROJACARTAGENA | K12: Sí | L12: Sí | M12: No | N12: No | O12: Sí | P12: 6 | Q12: 3 | R12: 2 | S12: 0 | T12: 1 | U12: No | V12: Sí | W12: No | X12: Sí | Y12: No | Z12: Sí | AA12: Sí | AB12: Sí | AC12: No | AD12: Sí | AE12: No | AF12: 750 | AG12: 170 | AH12: 300 | AI12: 0 | AJ12: 0 | AK12: 13 | AL12: 0 | AM12: 2 | AN12: 2 | AO12: 9 | AP12: 0 | AQ12: 0 | AR12: 2 | AS12: 1 | AT12: 3 | AU12: 4 | AV12: 5 | AW12: Presencial | AX12: 3 | AY12: 2 | AZ12: 1 | BA12: 4 | BB12: Arriendo | BC12: policlínico, subvención municipal, donaciones | BD12: 1
B13: Castro | C13: Los Lagos y Aysén | D13: 13 | E13: 0 | F13: 70672777-9 | G13: GAmbia 535 Castro | H13: 652633133 | I13: 44197 | K13: No | L13: Sí | M13: No | N13: No | O13: Sí | P13: 2 | Q13: 2 | R13: 0 | S13: 2 | T13: 2 | U13: No | V13: No | W13: Sí | X13: Sí | Y13: Sí | Z13: Sí | AA13: Sí | AB13: No | AC13: No | AD13: Sí | AE13: No | AF13: 105 | AG13: 105 | AH13: 120 | AI13: 0 | AJ13: 0 | AK13: 0 | AL13: 0 | AM13: 0 | AN13: 0 | AO13: 0 | AP13: 0 | AQ13: 0 | AR13: 5 | AS13: 3 | AT13: 1 | AU13: 2 | AV13: 4 | AW13: Presencial | AX13: 2 | AY13: 3 | AZ13: 1 | BA13: 4 | BB13: Arriendo | BC13: aporte de voluntariados, beneficios, socios colaboradores, campaña del sobre | BD13: 1
B14: Cauquenes | C14: Maule | D14: 22 | E14: 0 | F14: 65015007-4 | G14: Antonio Varas 1019 | H14: 976570039 | I14: S/I | K14: Sí | L14: Sí | M14: No | N14: Sí | O14: Sí | P14: 20 | Q14: 8 | R14: 3 | S14: 0 | T14: 0 | U14: No | V14: No | W14: No | X14: No | Y14: Sí | Z14: Sí | AA14: No | AB14: Sí | AC14: No | AD14: No | AE14: No | AF14: 120 | AG14: 43 | AH14: 45 | AI14: 4 | AJ14: 0 | AK14: 0 | AL14: 0 | AM14: 3 | AN14: 0 | AO14: 0 | AP14: 0 | AQ14: 0 | AR14: 5 | AS14: 4 | AT14: 2 | AU14: 1 | AV14: 3 | AW14: Presencial | AX14: 1 | AY14: 2 | AZ14: 3 | BA14: 4 | BB14: Arriendo | BD14: 1
B15: Chiguayante | C15: Biobío y Ñuble | D15: 47 | E15: 6 | F15: 70672722-1 | G15: Prat 80 | H15: 979388879 | I15: 44531 | J15: crz_roja_juventud_chiguayante | K15: Sí | L15: Sí | M15: Sí | N15: No | O15: Sí | P15: 6 | Q15: 6 | R15: 0 | S15: 4 | T15: 1 | U15: Sí | V15: Sí | W15: Sí | X15: Sí | Y15: No | Z15: Sí | AA15: Sí | AB15: Sí | AC15: No | AD15: Sí | AE15: Sí | AF15: 230 | AG15: 82 | AH15: 60 | AI15: 0 | AJ15: 0 | AK15: 0 | AL15: 0 | AM15: 0 | AN15: 0 | AO15: 2 | AP15: 0 | AQ15: 0 | AR15: 1 | AS15: 2 | AT15: 3 | AU15: 4 | AV15: 5 | AW15: Presencial | AX15: 3 | AY15: 2 | AZ15: 1 | BA15: 4 | BB15: Subvencíón municipal | BD15: 0
B16: Chillán | C16: Biobío y Ñuble | D16: 33 | E16: 9 | F16: 70512195-8 | G16: Maipón 301 Chillán | H16: 993204220 | I16: 43678 | J16: cruzrojachilena.chillan | K16: Sí | L16: Sí | M16: Sí | N16: Sí | O16: Sí | P16: 4 | Q16: 8 | R16: 0 | S16: 4 | T16: 3 | U16: Sí | V16: No | W16: No | X16: Sí | Y16: Sí | Z16: Sí | AA16: Sí | AB16: No | AC16: Sí | AD16: Sí | AE16: Sí | AF16: 15 | AG16: 213 | AH16: 219 | AI16: 2 | AJ16: 4 | AK16: 0 | AL16: 1 | AM16: 0 | AN16: 0 | AO16: 146 | AP16: 0 | AQ16: 5 | AR16: 2 | AS16: 5 | AT16: 1 | AU16: 3 | AV16: 4 | AW16: Presencial | AX16: 1 | AY16: 2 | AZ16: 3 | BA16: 4 | BB16: Cursos PAA | BC16: Subvención municipal de proyectos específicos | BD16: 1
B17: Coelemu | C17: Biobío y Ñuble | D17: 9 | E17: 2 | F17: 70512197-4 | G17: Palazuelos 265 | H17: 923710907 | I17: 2016 | J17: Cruzrojacoelemu | K17: Sí | L17: Sí | M17: No | N17: Sí | O17: Sí | P17: 2 | Q17: 2 | R17: 2 | S17: 1 | T17: 1 | U17: No | V17: No | W17: No | X17: No | Y17: Sí | Z17: Sí | AA17: Sí | AB17: Sí | AC17: Sí | AD17: Sí | AE17: No | AF17: 73 | AG17: 35 | AH17: 0 | AI17: 1 | AJ17: 2 | AK17: 0 | AL17: 1 | AM17: 1 | AN17: 3 | AO17: 57 | AP17: 0 | AQ17: 0 | AR17: 2 | AS17: 5 | AT17: 4 | AU17: 1 | AV17: 3 | AW17: Mixta | AX17: 1 | AY17: 3 | AZ17: 2 | BA17: 4 | BB17: Arriendo | BD17: 1
B18: Collipulli | C18: Araucanía | D18: 24 | E18: 4 | F18: 70672738-8 | G18: Calle Cruz N16 | H18: 987504663 | I18: 45444 | J18: cr.filialcollipulli | K18: Sí | L18: Sí | M18: No | N18: No | O18: Sí | P18: 8 | Q18: 8 | R18: 1 | S18: 0 | T18: 0 | U18: No | V18: No | W18: Sí | X18: Sí | Y18: No | Z18: Sí | AA18: No | AB18: No | AC18: No | AD18: No | AE18: No | AF18: 8 | AG18: 10 | AH18: 20 | AI18: 0 | AJ18: 0 | AK18: 0 | AL18: 0 | AM18: 0 | AN18: 0 | AO18: 0 | AP18: 0 | AQ18: 0 | AR18: 3 | AS18: 5 | AT18: 1 | AU18: 2 | AV18: 4 | AW18: Online | AX18: 2 | AY18: 4 | AZ18: 1 | BA18: 3 | BB18: Otro | BC18: Donaciones | BD18: 1
B19: Concepción | C19: Biobío y Ñuble | D19: 76 | E19: 2 | F19: 70672724-8 | G19: Lautaro 509 | H19: 412954653 | I19: 45566 | J19: Cruz.roja.concepcion | K19: Sí | L19: Sí | M19: Sí | N19: Sí | O19: Sí | P19: 10 | Q19: 11 | R19: 3 | S19: 4 | T19: 1 | U19: No | V19: No | W19: No | X19: Sí | Y19: Sí | Z19: Sí | AA19: Sí | AB19: Sí | AC19: No | AD19: No | AE19: No | AF19: 93 | AG19: 34 | AH19: 27 | AI19: 3 | AJ19: 1 | AK19: 0 | AL19: 2 | AM19: 1 | AN19: 0 | AO19: 137 | AP19: 0 | AQ19: 2 | AR19: 5 | AS19: 2 | AT19: 1 | AU19: 3 | AV19: 4 | AW19: Presencial | AX19: 1 | AY19: 2 | AZ19: 4 | BA19: 3 | BB19: Cursos PAA | BD19: 1
B20: Concón | C20: Valparaíso | D20: 14 | E20: 8 | F20: S/I | G20: Av. Reñaca Concón con los Alerces | H20: 985768450 | I20: S/I | J20: CRUZ ROJA CONCON | K20: Sí | L20: Sí | M20: Sí | N20: No | O20: Sí | P20: 6 | Q20: 6 | R20: 0 | S20: 1 | T20: 0 | U20: Sí | V20: Sí | W20: Sí | X20: No | Y20: Sí | Z20: Sí | AA20: Sí | AB20: No | AC20: Sí | AD20: Sí | AE20: Sí | AF20: 0 | AG20: 0 | AH20: 0 | AI20: 0 | AJ20: 0 | AK20: 0 | AL20: 0 | AM20: 0 | AN20: 0 | AO20: 0 | AP20: 0 | AQ20: 0 | AR20: 1 | AS20: 2 | AT20: 5 | AU20: 4 | AV20: 3 | AW20: Online | AX20: 2 | AY20: 1 | AZ20: 4 | BA20: 3 | BB20: Subvencíón municipal | BD20: 0
B21: Copiapó | C21: Atacama-Coquimbo | D21: 20 | E21: 6 | F21: 70672709-4 | G21: Chañarcillo n°300 | H21: 981820329 | I21: 44652 | K21: No | L21: Sí | M21: Sí | N21: Sí | O21: Sí | P21: 2 | Q21: 8 | R21: 7 | S21: 1 | T21: 2 | U21: No | V21: No | W21: Sí | X21: Sí | Y21: Sí | Z21: Sí | AA21: No | AB21: Sí | AC21: No | AD21: Sí | AE21: Sí | AF21: 100 | AG21: 30 | AH21: 10 | AI21: 0 | AJ21: 2 | AK21: 0 | AL21: 2 | AM21: 2 | AN21: 1 | AO21: 0 | AP21: 0 | AQ21: 0 | AR21: 1 | AS21: 5 | AT21: 4 | AU21: 2 | AV21: 3 | AW21: Online | AX21: 4 | AY21: 1 | AZ21: 2 | BA21: 3 | BB21: Otro | BC21: Aporte voluntarios, aportes de rifa beneficio filial | BD21: 1
B22: Coquimbo | C22: Atacama-Coquimbo | D22: 17 | E22: 10 | F22: 70672713-2 | G22: Melgarejo 1035 | H22: 51 2311166 | I22: S/I | J22: @filialcoquimbo | K22: Sí | L22: Sí | M22: Sí | N22: No | O22: Sí | P22: S/I | Q22: S/I | R22: 0 | S22: 0 | T22: 0 | U22: No | V22: Sí | W22: Sí | X22: Sí | Y22: Sí | Z22: No | AA22: No | AB22: No | AC22: No | AD22: Sí | AE22: No | AF22: 0 | AG22: 0 | AH22: 0 | AI22: 0 | AJ22: 3 | AK22: 0 | AL22: 6 | AM22: 2 | AN22: 0 | AO22: 0 | AP22: 4 | AQ22: 0 | AR22: 3 | AS22: 5 | AT22: 2 | AU22: 1 | AV22: 4 | AW22: Mixta | AX22: 3 | AY22: 2 | AZ22: 1 | BA22: 4 | BB22: Policlínico | BD22: 1
B23: Cordillera | C23: Valparaíso | D23: 23 | E23: 0 | F23: 70512163-K | G23: Cahaparro 90 Cerro Cordillera Valparaíso | H23: 945802224 | I23: 45474 | J23: filial.cordillera | K23: Sí | L23: Sí | M23: No | N23: No | O23: Sí | P23: 8 | Q23: 1 | R23: 3 | S23: 1 | T23: 0 | U23: Sí | V23: No | W23: Sí | X23: Sí | Y23: No | Z23: Sí | AA23: Sí | AB23: Sí | AC23: Sí | AD23: Sí | AE23: Sí | AF23: 50 | AG23: 30 | AH23: 50 | AI23: 1 | AJ23: 0 | AK23: 2 | AL23: 2 | AM23: 1 | AN23: 0 | AO23: 0 | AP23: 0 | AQ23: 0 | AR23: 3 | AS23: 2 | AT23: 4 | AU23: 1 | AV23: 5 | AW23: Presencial | AX23: 3 | AY23: 2 | AZ23: 1 | BA23: 4 | BB23: Otro | BC23: Donaciones y Beneficios | BD23: 1
B24: Coyhaique | C24: Los Lagos y Aysén | D24: 10 | E24: 0 | F24: 70672779-5 | G24: Las Quintas 808 | H24: 56977997 | I24: S/I | J24: CRUZROJACHILENA_COYHAIQUE | K24: Sí | L24: Sí | M24: No | N24: No | O24: Sí | P24: 5 | Q24: 5 | R24: 0 | S24: 0 | T24: 0 | U24: No | V24: No | W24: Sí | X24: Sí | Y24: Sí | Z24: Sí | AA24: Sí | AB24: No | AC24: No | AD24: No | AE24: No | AF24: 30 | AG24: 0 | AH24: 20 | AI24: 0 | AJ24: 0 | AK24: 0 | AL24: 0 | AM24: 0 | AN24: 0 | AO24: 0 | AP24: 0 | AQ24: 0 | AR24: 3 | AS24: 4 | AT24: 1 | AU24: 2 | AV24: 5 | AW24: Presencial | AX24: 3 | AY24: 2 | AZ24: 1 | BA24: 4 | BB24: Otro | BC24: Beneficio venta de empanadas | BD24: 0
B25: Curanilahue | C25: Biobío y Ñuble | D25: 11 | E25: 9 | F25: 70512192-3 | G25: Calle nueva S/N, Curanilahue | H25: 962051572 | I25: 44409 | K25: No | L25: No | M25: No | N25: Sí | O25: Sí | P25: 10 | Q25: 11 | R25: 0 | S25: 0 | T25: 0 | U25: No | V25: No | W25: No | X25: Sí | Y25: No | Z25: Sí | AA25: No | AB25: No | AC25: No | AD25: Sí | AE25: Sí | AF25: 92 | AG25: 105 | AH25: 0 | AI25: 0 | AJ25: 0 | AK25: 0 | AL25: 0 | AM25: 11 | AN25: 2 | AO25: 10 | AP25: 0 | AQ25: 0 | AR25: 1 | AS25: 3 | AT25: 4 | AU25: 5 | AV25: 2 | AW25: Presencial | AX25: 4 | AY25: 3 | AZ25: 2 | BA25: 1 | BB25: Subvencíón municipal | BD25: 0
B26: Curicó | C26: Maule | D26: 31 | E26: 13 | F26: 70512145-1 | G26: Estado 206 Curicó | H26: 927615972 | I26: 44927 | J26: cruzrojacurico | K26: Sí | L26: Sí | M26: Sí | N26: Sí | O26: Sí | P26: 2 | Q26: 1 | R26: 0 | S26: 1 | T26: 1 | U26: No | V26: No | W26: Sí | X26: Sí | Y26: No | Z26: Sí | AA26: No | AB26: No | AC26: No | AD26: Sí | AE26: Sí | AF26: 20 | AG26: 30 | AH26: 40 | AI26: 4 | AJ26: 2 | AK26: 1 | AL26: 0 | AM26: 0 | AN26: 0 | AO26: 60 | AP26: 1 | AQ26: 0 | AR26: 1 | AS26: 3 | AT26: 4 | AU26: 5 | AV26: 2 | AW26: Presencial | AX26: 3 | AY26: 2 | AZ26: 4 | BA26: 1 | BB26: Arriendo | BD26: 1
B27: El Loa | C27: Antofagasta | D27: 58 | E27: 10 | F27: 70672703-5 | G27: Balmaceda 1932 Calama | H27: 973650711 | I27: 45413 | J27: instagram | K27: Sí | L27: Sí | M27: No | N27: No | O27: Sí | P27: 5 | Q27: 25 | R27: 1 | S27: 0 | T27: 3 | U27: No | V27: Sí | W27: Sí | X27: Sí | Y27: Sí | Z27: Sí | AA27: No | AB27: Sí | AC27: Sí | AD27: Sí | AE27: No | AF27: 150 | AG27: 150 | AH27: 150 | AI27: 0 | AJ27: 0 | AK27: 0 | AL27: 2 | AM27: 1 | AN27: 1 | AO27: 60 | AP27: 0 | AQ27: 2 | AR27: 5 | AS27: 3 | AT27: 1 | AU27: 2 | AV27: 4 | AW27: Presencial | AX27: 3 | AY27: 4 | AZ27: 1 | BA27: 2 | BB27: Arriendo | BC27: Subvención Municipal | BD27: 1
B28: El Monte | C28: Metropolitana | D28: 11 | E28: 3 | F28: 70512117-6 | G28: Ignacio Carrera Pinto 044 | H28: 982383360 | I28: 2001 | J28: Cruz_roja_filial_el_monte | K28: Sí | L28: Sí | M28: No | N28: No | O28: Sí | P28: 6 | Q28: 6 | R28: 0 | S28: 0 | T28: 0 | U28: No | V28: No | W28: Sí | X28: Sí | Y28: Sí | Z28: Sí | AA28: No | AB28: No | AC28: No | AD28: Sí | AE28: No | AF28: 0 | AG28: 20 | AH28: 20 | AI28: 0 | AJ28: 0 | AK28: 0 | AL28: 0 | AM28: 0 | AN28: 1 | AO28: 0 | AP28: 0 | AQ28: 0 | AR28: 5 | AS28: 4 | AT28: 1 | AU28: 2 | AV28: 3 | AW28: Presencial | AX28: 3 | AY28: 1 | AZ28: 2 | BA28: 4 | BB28: Otro | BC28: atención podológica | BD28: 1
B29: El Quisco | C29: Valparaíso | D29: 10 | E29: 0 | F29: 70512163-K | G29: Alcalde Raul Romero Erazo 0375 | H29: 995985661 | I29: S/I | J29: cruzrojaelquisco | K29: Sí | L29: Sí | M29: Sí | N29: Sí | O29: Sí | P29: 4 | Q29: 4 | R29: 0 | S29: 1 | T29: 1 | U29: Sí | V29: No | W29: Sí | X29: Sí | Y29: Sí | Z29: Sí | AA29: Sí | AB29: No | AC29: No | AD29: No | AE29: No | AF29: 300 | AG29: 250 | AH29: 150 | AI29: 0 | AJ29: 0 | AK29: 0 | AL29: 0 | AM29: 0 | AN29: 0 | AO29: 0 | AP29: 0 | AQ29: 0 | AR29: 1 | AS29: 2 | AT29: 3 | AU29: 5 | AV29: 4 | AW29: Mixta | AX29: 1 | AY29: S/I | AZ29: 2 | BA29: S/I | BB29: Cursos PAA | BC29: y subvención municipal | BD29: 0
B30: Frutillar | C30: Los Lagos y Aysén | D30: 13 | E30: 3 | F30: 70672769-2 | G30: Anibal Pinto 153 | H30: 950169720 | I30: 44501 | K30: No | L30: No | M30: Sí | N30: Sí | O30: Sí | P30: 3 | Q30: 3 | R30: 0 | S30: 0 | T30: 0 | U30: Sí | V30: No | W30: Sí | X30: No | Y30: No | Z30: Sí | AA30: Sí | AB30: Sí | AC30: No | AD30: No | AE30: No | AF30: 0 | AG30: 0 | AH30: 0 | AI30: 0 | AJ30: 0 | AK30: 0 | AL30: 0 | AM30: 0 | AN30: 0 | AO30: 0 | AP30: 0 | AQ30: 0 | AR30: 4 | AS30: 3 | AT30: 1 | AU30: 2 | AV30: 5 | AW30: Online | AX30: S/I | AY30: S/I | AZ30: S/I | BA30: S/I | BB30: Arriendo | BD30: 0
B31: Gorbea | C31: Araucanía | D31: 21 | E31: 0 | F31: 70672750-7 | G31: Cochrane N° 401 Gorbea | H31: 978736669 | I31: S/I | J31: Cruz_Roja_gorbea | K31: Sí | L31: Sí | M31: Sí | N31: No | O31: Sí | P31: 21 | Q31: 21 | R31: 0 | S31: 0 | T31: 0 | U31: No | V31: No | W31: No | X31: Sí | Y31: No | Z31: Sí | AA31: Sí | AB31: No | AC31: No | AD31: No | AE31: Sí | AF31: 0 | AG31: 0 | AH31: 0 | AI31: 2 | AJ31: 0 | AK31: 0 | AL31: 0 | AM31: 7 | AN31: 2 | AO31: 0 | AP31: 1 | AQ31: 0 | AR31: 5 | AS31: 4 | AT31: 3 | AU31: 2 | AV31: 1 | AW31: Presencial | AX31: 4 | AY31: 2 | AZ31: 1 | BA31: 4 | BB31: Subvencíón municipal | BC31: y comedor social | BD31: 0
B32: Illapel | C32: Atacama-Coquimbo | D32: 12 | E32: 2 | F32: 70672715-9 | G32: Ramón Freire # 350 | H32: 532523101 | I32: en proceso | K32: No | L32: No | M32: No | N32: No | O32: Sí | P32: S/I | Q32: S/I | R32: 0 | S32: 0 | T32: 0 | U32: Sí | V32: No | W32: No | X32: Sí | Y32: No | Z32: Sí | AA32: No | AB32: No | AC32: No | AD32: Sí | AE32: Sí | AF32: 87 | AG32: 48 | AH32: 15 | AI32: 0 | AJ32: 0 | AK32: 0 | AL32: 0 | AM32: 0 | AN32: 0 | AO32: 0 | AP32: 1 | AQ32: 0 | AR32: 1 | AS32: 2 | AT32: 3 | AU32: 4 | AV32: 5 | AW32: Online | AX32: S/I | AY32: S/I | AZ32: 1 | BA32: S/I | BB32: Arriendo | BC32: Y box dental | BD32: 0
B33: Iquique | C33: Arica Parinacota Tarapacá | D33: 24 | E33: 20 | F33: 70.672.701-9 | G33: Obispo Labbé #800 | H33: 572344939 | I33: S/I | J33: cruzroja.filial.iquique | K33: Sí | L33: Sí | M33: Sí | N33: Sí | O33: Sí | P33: 5 | Q33: 15 | R33: 1 | S33: 3 | T33: 1 | U33: Sí | V33: Sí | W33: Sí | X33: Sí | Y33: No | Z33: Sí | AA33: Sí | AB33: No | AC33: No | AD33: Sí | AE33: Sí | AF33: 1500 | AG33: 1500 | AH33: 1500 | AI33: 1 | AJ33: 1 | AK33: 30 | AL33: 9 | AM33: 0 | AN33: 1 | AO33: 500 | AP33: 0 | AQ33: 0 | AR33: 5 | AS33: 4 | AT33: 3 | AU33: 2 | AV33: 1 | AW33: Mixta | AX33: 1 | AY33: 2 | AZ33: 3 | BA33: 4 | BB33: Cursos PAA | BC33: y policlínicos | BD33: 0
B34: La Cisterna | C34: Metropolitana | D34: 11 | E34: 1 | F34: 70512119-2 | G34: Pablo Goyeneche 17 | H34: 986284017 | I34: 45566 | J34: Lacisterna.oficial | K34: Sí | L34: Sí | M34: No | N34: No | O34: Sí | P34: 4 | Q34: 5 | R34: 1 | S34: 1 | T34: 0 | U34: No | V34: No | W34: Sí | X34: Sí | Y34: No | Z34: Sí | AA34: Sí | AB34: No | AC34: No | AD34: Sí | AE34: No | AF34: 35 | AG34: 325 | AH34: 0 | AI34: 0 | AJ34: 0 | AK34: 0 | AL34: 1 | AM34: 0 | AN34: 1 | AO34: 49 | AP34: 0 | AQ34: 0 | AR34: 5 | AS34: 4 | AT34: 1 | AU34: 2 | AV34: 3 | AW34: Online | AX34: 1 | AY34: 3 | AZ34: 2 | BA34: 4 | BB34: Cursos PAA | BC34: y subvención municipal | BD34: 0
B35: La Serena | C35: Atacama-Coquimbo | F35: 70672711-6 | G35: Cienfuegos 470 | H35: 967252337 | I35: 44774 | K35: Sí | L35: No | M35: No | N35: Sí | O35: No | P35: 0 | Q35: 0 | R35: 0 | S35: 2 | T35: 0 | U35: Sí | V35: No | W35: Sí | X35: Sí | Y35: Sí | Z35: Sí | AA35: Sí | AB35: No | AC35: No | AD35: Sí | AE35: No | AF35: 0 | AG35: 0 | AH35: 0 | AI35: 0 | AJ35: 0 | AK35: 0 | AL35: 0 | AM35: 0 | AN35: 0 | AO35: 12 | AP35: 3 | AQ35: 0 | AR35: 1 | AS35: 2 | AT35: 3 | AU35: 4 | AV35: 5 | AW35: Presencial | AX35: 1 | AY35: 2 | AZ35: 4 | BA35: 3 | BB35: Policlínico | BC35: Y arriendos | BD35: 1
B36: La Unión | C36: Los Ríos | F36: 70672760-4 | G36: Barros Arana 569 | H36: 642322528 | I36: 44562 | J36: CRUZ ROJA-LU | K36: Sí | L36: Sí | M36: Sí | N36: Sí | O36: Sí | P36: 4 | Q36: 4 | R36: 0 | S36: 0 | T36: 0 | U36: No | V36: No | W36: Sí | X36: Sí | Y36: No | Z36: Sí | AA36: Sí | AB36: Sí | AC36: No | AD36: No | AE36: Sí | AF36: 283 | AG36: 3504 | AH36: 0 | AI36: 0 | AJ36: 0 | AK36: 0 | AL36: 0 | AM36: 0 | AN36: 0 | AO36: 0 | AP36: 1 | AQ36: 0 | AR36: 3 | AS36: 2 | AT36: 1 | AU36: 4 | AV36: 5 | AW36: Presencial | AX36: S/I | AY36: 1 | AZ36: 2 | BA36: S/I | BD36: 1
B37: Lago Ranco | C37: Los Ríos | F37: 70672763-9 | G37: Calle Valparaíso SN | H37: 944903828 | I37: S/I | K37: Sí | L37: Sí | M37: No | N37: Sí | O37: No | P37: 0 | Q37: 0 | R37: 0 | S37: 0 | T37: 0 | U37: Sí | V37: No | W37: No | X37: No | Y37: Sí | Z37: Sí | AA37: Sí | AB37: Sí | AC37: No | AD37: No | AE37: No | AF37: 20 | AG37: 99 | AH37: 0 | AI37: 0 | AJ37: 0 | AK37: 0 | AL37: 0 | AM37: 0 | AN37: 0 | AO37: 0 | AP37: 0 | AQ37: 0 | AR37: 2 | AS37: 1 | AT37: 3 | AU37: 4 | AV37: 5 | AW37: Presencial | AX37: 3 | AY37: 2 | AZ37: 1 | BA37: 4 | BD37: 1
B38: Lanco | C38: Los Ríos | F38: 70672755-8 | G38: Calle Valparaíso Recinto casas tuteladas | H38: - | I38: S/I | K38: Sí | L38: Sí | M38: Sí | N38: No | O38: Sí | P38: 0 | Q38: 9 | R38: 0 | S38: 0 | T38: 0 | U38: No | V38: No | W38: No | X38: Sí | Y38: No | Z38: No | AA38: Sí | AB38: No | AC38: No | AD38: Sí | AE38: No | AF38: 0 | AG38: 0 | AH38: 0 | AI38: 0 | AJ38: 0 | AK38: 0 | AL38: 0 | AM38: 0 | AN38: 0 | AO38: 0 | AP38: 0 | AQ38: 0 | AR38: 2 | AS38: 1 | AT38: 3 | AU38: 4 | AV38: 5 | AW38: Presencial | AX38: 3 | AY38: 2 | AZ38: 1 | BA38: 4 | BB38: Subvencíón municipal | BD38: 1
B39: Lastarria | C39: Araucanía | F39: 75327500-2 | G39: 18 de sept 489, lastarria | H39: 989151454 | I39: 45413 | K39: Sí | L39: Sí | M39: No | N39: No | O39: Sí | P39: 4 | Q39: 5 | R39: 0 | S39: 0 | T39: 0 | U39: No | V39: No | W39: No | X39: No | Y39: No | Z39: Sí | AA39: No | AB39: Sí | AC39: No | AD39: No | AE39: Sí | AF39: 70 | AG39: 15 | AH39: 0 | AI39: 0 | AJ39: 0 | AK39: 0 | AL39: 0 | AM39: 0 | AN39: 0 | AO39: 0 | AP39: 0 | AQ39: 0 | AR39: 2 | AS39: 3 | AT39: 1 | AU39: 4 | AV39: 5 | AW39: Presencial | AX39: 1 | AY39: 3 | AZ39: 4 | BA39: 2 | BB39: Otro | BC39: Coronas de caridad | BD39: 0
B40: Lebu | C40: Biobío y Ñuble | F40: 70672734-5 | G40: Saavedra 539 Lebu | H40: 998656463 | I40: 45261 | K40: No | L40: Sí | M40: Sí | N40: Sí | O40: Sí | P40: 0 | Q40: 1 | R40: 0 | S40: 4 | T40: 0 | U40: No | V40: No | W40: Sí | X40: Sí | Y40: Sí | Z40: Sí | AA40: Sí | AB40: Sí | AC40: Sí | AD40: Sí | AE40: Sí | AF40: 35 | AG40: 36 | AH40: 19 | AI40: 2 | AJ40: 0 | AK40: 0 | AL40: 1 | AM40: 1 | AN40: 1 | AO40: 74 | AP40: 0 | AQ40: 0 | AR40: 1 | AS40: 2 | AT40: 4 | AU40: 3 | AV40: 5 | AW40: Presencial | AX40: 3 | AY40: 2 | AZ40: 1 | BA40: 4 | BB40: Arriendo | BD40: 1
...

Sheet Sugerencias
A1: Filial | B1: Comentario
A2: Almendral | B2: S/I
A3: Angol | B3: S/I
A4: Antofagasta | B4: Como sugerencia sería implementar en base a la transparencia e igualdad que el Gobierno y la Junta para los cursosvenideros con fondos internacionales sean más participativos; es decir que sea con una postulación a nivel nacional y no elegidos por comités o Direcciones Nacionales, esto en base a que estoy seguro que dentro del voluntariado a nivel Nacional existe más de una persona con las competencia para que pueda adquirir los conocimientos de dicho curso; me baso en que vemos que asisten a cursos a nivel internacional y no se tiene mayor información de lo expuesto, quizás la retroalimentación la obtiene la filial o comité al cual pertenece el voluntario pero para la mayor igualdad sería bueno que estos conocimientos sean compartidos a través de una plataforma virtual para que todo el voluntariado a nivel nacional lo pueda adquirir.
A5: Arica y Parinacota | B5: S/I
A6: Bulnes | B6: NOSOTROS COMO FILIAL BULNES NECESITAMOS MAYOR APOYO EN LAS GESTIONES , PARA PODER ADMINISTRAR DE MEJOR FORMA EL HOGAR DE ANCIANOS, YA QUE ESTAMOS OFRECIENDO UNA LABOR EN LA COMUNIDAD PARA LAS PERSONAS MAYORES VULNERBLES ABANDONADAS POR LA FAMILIA Y SOCIEDAD,TENEMOS PRESENCIA,CREDIBILIDAD , CONFIABILIDAD,DEJANDO BIEN A LA INSTITUCION , PERO LOS RECURSOS QUE HACEN POCOS, SE REQUIERE APOYO DEL NIVEL CENTRAL, SIEMPRE ESTAMOS NECESITANDO RECURSOS ECONOMICOS, ALIMENTOS, VESTUARIOS IMPLEMENTOS PARA EL FUNCIONAMNIENTO.EL MUNICIPIO HA SIDO UN GRAN APOYO PERO NO ES SUFIECIENTE ENE STOS TIEMPOOS YA QUE SE REQUIERE UN POCO MAS.- Muchas veces nos sentimos SOLAS y sin apoyo Pero no podemos dejar de agradecer al comité regional Bio Bio-Ñuble ,por el apoyo permanente, cuando pueden hacerlo.- Si se necesita el respaldo COMITÉ CENTRAL EN GESTIONES IMPORTANTES,Y APOYO ECONOMICO, marerial
A7: Cabrero | B7: Siempre orgullosos y orgullosas del trabajo realizado y de pertenecer a esta hermosa y loable institución. Por nuestra parte sugerimos una acceso para amplio y fácil a poder capacitar a nuestros voluntarios y voluntarias en primeros auxilios por voluntarios del área de la salud, que pudiesen no contar con título de instructoría desde CR, pero si conocimientos del área por ámbito profesional, eso facilitaría este proceso sobre todo pensando en que ya es complejo poder contar con disponibilidad para participar activamente de actividades de filial, es aún más complejo poder asistir a otros lugares a capacitarse , por disponibilidad de tiempo, económica, etc.
A8: Caldera | B8: S/I
A9: Cañete | B9: S/I
A10: Capitán Pastene | B10: Nuestra Filial se encuentra en un lugar apartado de los centros urbanos más importantes de la región de La Araucanía. Esto ha dificultado la posibilidad de recibir la formación en Primeros Auxilios y Doctrina Institucional, principalmente. Aún así, nos hemos integrado a campañas y actividades regionales y nacionales. También hemos sido referente y centro de operaciones durante los incendios en que recibimos la intervención del Proyecto DREF. En cuanto a financiamiento, la colecta anual en la semana de Cruz Roja, es muy importante para financiar actividades y generar ayudas que entregamos a la comunidad consistente, principalmente, en medicamentos, alimentos especiales, exámenes médicos, canastas familiares, etc. Nuestros ingresos se obtienen mediante la participación en Ferias Gastronómicas de comidas italianas. Esto es una vez al año y lo que ofrecemos es confeccionado por el voluntariado. Adolecemos de conocimientos y expertis en tecnología, lo que hace difícil la entrega de Balance y Memoria Anual. Toda la documentación que requiere esta destreza nos significa una dificultad, la que salvamos con ayuda externa de personas de buena voluntad, asumiendo la responsabilidad que nos asiste como Cruces Rojas comprometidas con nuestra querida Institución.
A11: Carahue | B11: - CAPACITACION COMPUTACIONAL GENERAL. - CAPACITACION EN BALANCES. - ETICA Y DOCTRINA.
A12: Cartagena | B12: CAPACITACION EN FILIAL O ZONA COSTA POR TIEMPO Y COSTOS. (PRESENCIAL DESDE SEDE CENTRAL A FILIAL)
... A113: Yungay | B113: APOYAR LAS FILIALES PARA PODER GESTIONAR DIFERENTES PROYECTO, SUBVENCIONES, ETC. PARA SI PODER TENER MAYOR CONOCIMIENTOS DE ESTOS Y PODER CONSERVAR Y ARREGLAR LAS FILIALES.

Sheet Validación formularios
C2: Sede Regional | D2: Presidente | E2: Fono Sede | F2: Fono Celular | G2: Correo electrónico | H2: Memoria regional | J2: Alto Hospicio | K2: =VLOOKUP(J2,'Datos filial'!$B$2:$B$148,1,0) -> #N/A | L2: =IF(K2=J2,"OK","NOK") -> #N/A | M2: en receso
B3: XV-I | C3: Arica Parinacota Tarapacá | D3: Berta Aravena Bustamante | E3: 57 - 2344939 | F3: 569 88895009 | G3: regional.primera@cruzroja.cl | J3: Lautaro | K3: =VLOOKUP(J3,'Datos filial'!$B$2:$B$148,1,0) -> #N/A | L3: =IF(K3=J3,"OK","NOK") -> #N/A | M3: En receso
B4: II | C4: Antofagasta | D4: Héctor Castillo | E4: 55 - 2847328 | F4: 569 67961903 | G4: regional.segunda@cruzroja.cl | H4: OK | J4: Freire | K4: =VLOOKUP(J4,'Datos filial'!$B$2:$B$148,1,0) -> #N/A | L4: =IF(K4=J4,"OK","NOK") -> #N/A | M4: Cerrada
B5: III-IV | C5: Atacama-Coquimbo | D5: Virginia Frías Bulo | E5: 51 - 2219994 | F5: 569 92400633 | G5: regional.tercera@cruzroja.cl | H5: OK | J5: Teodoro Schmidt | K5: =VLOOKUP(J5,'Datos filial'!$B$2:$B$148,1,0) -> #N/A | L5: =IF(K5=J5,"OK","NOK") -> #N/A | M5: Cerrada
B6: V | C6: Valparaíso | D6: Cecilia Pedreros Barrera | E6: 32 - 2883307 | F6: 569 99987499 | G6: regional.quinta@cruzroja.cl | H6: OK | J6: Puerto Aysén | K6: =VLOOKUP(J6,'Datos filial'!$B$2:$B$148,1,0) -> #N/A | L6: =IF(K6=J6,"OK","NOK") -> #N/A | M6: Cerrada
B7: VI | C7: Bernardo O'Higgins | D7: Raquel Oyarzún Reyes | E7: 72 - 2240204 | F7: 569 81370465 | G7: regional.sexta@cruzroja.cl | H7: OK
B8: VII | C8: Maule | D8: Juana Barraza Gaete | E8: 71 - 2211994 | F8: 569 68985175 | G8: regional.septima@cruzroja.cl
B9: VIII-XVI | C9: Biobío y Ñuble | D9: Rosa Barrera Muñoz | E9: 41 - 2223367 | F9: 569 98328323 | G9: regional.octava@cruzroja.cl | H9: OK
B10: IX | C10: Araucanía | D10: Mariela Erices Labrin | E10: 45 - 2216715 | F10: 569 75593650 | G10: regional.novena@cruzroja.cl | H10: OK
B11: XIV | C11: Los Ríos | D11: Marisol Córdova Medina | E11: 63 - 2219709 | F11: 569 94663451 | G11: regional.losrios@cruzroja.cl | H11: OK
B12: X-XI | C12: Los Lagos y Aysén | D12: Silvia Muñoz Muñoz | E12: 65 - 2275827 | F12: 569 85830557 | G12: regional.decima@cruzroja.cl | H12: OK
B13: XII | C13: Magallanes y la Antártica | D13: María Luisa Cárcamo Barrientos | E13: 61 - 2228669 | F13: 569 88678879 | G13: regional.duodecima@cruzroja.cl
B14: RM | C14: Metropolitana | D14: No aplica
G15: Suma recibidos | H15: =COUNTA(H3:H14) -> 8
B16: Filial Original | C16: Filial recibida
A17: 1 | B17: Almendral | C17: =VLOOKUP(B17,'Datos filial'!$B$2:$B$148,1,0) -> Almendral | D17: =IF(C17=B17,"OK","NOK") -> OK
A18: 2 | B18: Ancud | C18: =VLOOKUP(B18,'Datos filial'!$B$2:$B$148,1,0) -> Ancud | D18: =IF(C18=B18,"OK","NOK") -> OK
A19: 3 | B19: Angol | C19: =VLOOKUP(B19,'Datos filial'!$B$2:$B$148,1,0) -> Angol | D19: =IF(C19=B19,"OK","NOK") -> OK
A20: 4 | B20: Antofagasta | C20: =VLOOKUP(B20,'Datos filial'!$B$2:$B$148,1,0) -> Antofagasta | D20: =IF(C20=B20,"OK","NOK") -> OK
A21: 5 | B21: Arica y Parinacota | C21: =VLOOKUP(B21,'Datos filial'!$B$2:$B$148,1,0) -> Arica y Parinacota | D21: =IF(C21=B21,"OK","NOK") -> OK
A22: 6 | B22: Bulnes | C22: =VLOOKUP(B22,'Datos filial'!$B$2:$B$148,1,0) -> Bulnes | D22: =IF(C22=B22,"OK","NOK") -> OK
A23: 7 | B23: Cabrero | C23: =VLOOKUP(B23,'Datos filial'!$B$2:$B$148,1,0) -> Cabrero | D23: =IF(C23=B23,"OK","NOK") -> OK
A24: 8 | B24: Caldera | C24: =VLOOKUP(B24,'Datos filial'!$B$2:$B$148,1,0) -> Caldera | D24: =IF(C24=B24,"OK","NOK") -> OK
A25: 9 | B25: Cañete | C25: =VLOOKUP(B25,'Datos filial'!$B$2:$B$148,1,0) -> Cañete | D25: =IF(C25=B25,"OK","NOK") -> OK
A26: 10 | B26: Capitán Pastene | C26: =VLOOKUP(B26,'Datos filial'!$B$2:$B$148,1,0) -> Capitán Pastene | D26: =IF(C26=B26,"OK","NOK") -> OK
A27: 11 | B27: Carahue | C27: =VLOOKUP(B27,'Datos filial'!$B$2:$B$148,1,0) -> Carahue | D27: =IF(C27=B27,"OK","NOK") -> OK
A28: 12 | B28: Cartagena | C28: =VLOOKUP(B28,'Datos filial'!$B$2:$B$148,1,0) -> Cartagena | D28: =IF(C28=B28,"OK","NOK") -> OK
... A160: 144 | B160: Yungay | C160: =VLOOKUP(B160,'Datos filial'!$B$2:$B$148,1,0) -> Yungay | D160: =IF(C160=B160,"OK","NOK") -> OK
C161: Recibidos filial | D161: =COUNTIF(D17:D160,"OK") -> 131
C162: Recibidos Sede regional | D162: =H15 -> 8
C163: Total recibidos | D163: =SUM(D161:D162) -> 139
C164: Total esperado | D164: =A160+11 -> 155
C165: % cumplimiento | D165: =D163/D164 -> 0.89677419

Sheet Campos desplegables
A3: Cargos | B3: Género | C3: Tipo Voluntario | D3: Financiamiento | E3: Capacitación | F3: Binario
A4: Presidente | B4: F | C4: Activo | D4: Arriendo | E4: Online | F4: Sí
A5: Vicepresidente | B5: M | C5: Llamada | D5: Policlínico | E5: Presencial | F5: No
A6: Secretario/a | B6: Otro | C6: Otro | D6: Cursos PAA | E6: Mixta
A7: Director/a de Desarrollo | D7: Subvencíón municipal
A8: Director/a de Finanzas | D8: Otro
A9: Director/a de Salud
A10: Director/a de Comunicaciones
A11: Director/a de Juventud
A12: Director/a de Bienestar social
A13: Director/a de Gestión del Riesgo
A14: Voluntario/a
